Workbook

Sheet Líneas
A1: N° | B1: Bloque | C1: Categoría | D1: Línea | E1: Partida | F1: Ubicación | G1: Códigos 2027 | H1: Ley 2026 (miles $) | I1: Vigente 2026 a agosto (miles $) | J1: Proyecto 2027 (miles $) | K1: Base DIPRES 2027 (miles $) | L1: Variación nominal | M1: Variación real | N1: Vs base DIPRES | O1: Veredicto | P1: Se suma en bloques | Q1: Ley 2026 incluida en convenio U. de Chile | R1: Nota
A2: 1 | B2: Directo | C2: Directo | D2: Aporte «Universidad de Chile» (convenio de actividades de interés nacional) | E2: 09 | F2: Educación · Subs. Educación Superior · Fortalecimiento ES Pública · 24.03.203 | G2: 90.02.24.03.203 | H2: 13537053 | I2: 14537053 | J2: 7869907 | K2: 13926920 | L2: =IF(OR(H2="",H2=0),"",J2/H2-1) -> -0.41863957 | M2: =IF(OR(H2="",H2=0),"",J2/(H2*'Supuestos y fuentes'!$B$5)-1) -> -0.43491404 | N2: =IF(OR(K2="",K2=0),"",J2/K2-1) -> -0.43491404 | O2: =IF(OR(H2="",H2=0),"Nuevo",IF(M2<=-0.995,"Desaparece",IF(M2<-'Supuestos y fuentes'!$B$6,"Baja",IF(M2>'Supuestos y fuentes'!$B$6,"Sube","Se mantiene")))) -> Baja | P2: Sí | Q2: No | R2: En 2027 el riesgo sísmico (glosa 05) y el CEAC (glosa 06) salen a líneas propias. Aun sumando las tres líneas, el total cae (ver fila «Total transferencias MINEDUC»). Glosa 04 2027: mantiene los 530 cupos.
A3: 2 | B3: Directo | C3: Directo | D3: Aporte al Programa de Medición de Riesgo Sísmico de la U. de Chile | E3: 09 | F3: Educación · Fortalecimiento ES Pública · 24.03.205 (línea nueva) | G3: 90.02.24.03.205 | H3: 437471 | J3: 450070 | K3: 0 | L3: =IF(OR(H3="",H3=0),"",J3/H3-1) -> 0.028799623 | M3: =IF(OR(H3="",H3=0),"",J3/(H3*'Supuestos y fuentes'!$B$5)-1) -> -3.6616513e-07 | N3: =IF(OR(K3="",K3=0),"",J3/K3-1) | O3: =IF(OR(H3="",H3=0),"Nuevo",IF(M3<=-0.995,"Desaparece",IF(M3<-'Supuestos y fuentes'!$B$6,"Baja",IF(M3>'Supuestos y fuentes'!$B$6,"Sube","Se mantiene")))) -> Se mantiene | P3: Sí | Q3: Sí | R3: 2026: monto mínimo fijado en la glosa 04 de la línea «Universidad de Chile» (no era línea propia).
A4: 3 | B4: Directo | C4: Directo | D4: Aporte al Centro de Extensión Artística y Cultural (CEAC) de la U. de Chile | E4: 09 | F4: Educación · Fortalecimiento ES Pública · 24.03.206 (línea nueva) | G4: 90.02.24.03.206 | H4: 3606692 | J4: 3710565 | K4: 0 | L4: =IF(OR(H4="",H4=0),"",J4/H4-1) -> 0.028800075 | M4: =IF(OR(H4="",H4=0),"",J4/(H4*'Supuestos y fuentes'!$B$5)-1) -> 7.2873005e-08 | N4: =IF(OR(K4="",K4=0),"",J4/K4-1) | O4: =IF(OR(H4="",H4=0),"Nuevo",IF(M4<=-0.995,"Desaparece",IF(M4<-'Supuestos y fuentes'!$B$6,"Baja",IF(M4>'Supuestos y fuentes'!$B$6,"Sube","Se mantiene")))) -> Se mantiene | P4: Sí | Q4: Sí | R4: 2026: monto mínimo de la glosa 04 de «Universidad de Chile». 2027 (glosa 01 y 06): Cultura transfiere estos recursos a Educación y la Subsecretaría de Educación Superior los traspasa a la U. de Chile para el CEAC, la Orquesta Sinfónica Nacional, el Ballet Nacional y la Camerata Vocal.
A5: 4 | B5: Directo | C5: Cultura | D5: CEAC U. de Chile — aporte directo desde Cultura | E5: 29 | F5: Cultura · Subs. Culturas y Artes · Instituciones Colaboradoras · 24.03.127 | G5: 01.03.24.03.127 | H5: 2165100 | I5: 2100141 | J5: 0 | K5: 2160625 | L5: =IF(OR(H5="",H5=0),"",J5/H5-1) -> -1 | M5: =IF(OR(H5="",H5=0),"",J5/(H5*'Supuestos y fuentes'!$B$5)-1) -> -1 | N5: =IF(OR(K5="",K5=0),"",J5/K5-1) -> -1 | O5: =IF(OR(H5="",H5=0),"Nuevo",IF(M5<=-0.995,"Desaparece",IF(M5<-'Supuestos y fuentes'!$B$6,"Baja",IF(M5>'Supuestos y fuentes'!$B$6,"Sube","Se mantiene")))) -> Desaparece | P5: Sí | Q5: No | R5: Desaparece en el Proyecto 2027.
A6: 5 | B6: Directo | C6: Cultura | D6: Universidades Públicas Colaboradoras en el Acceso al Arte y la Cultura | E6: 29 | F6: Cultura · Instituciones Colaboradoras · 24.02.005 (transferencia a MINEDUC) | G6: 01.03.24.02.005 | H6: 5870739 | I6: 4594569 | J6: 3710565 | K6: 4726893 | L6: =IF(OR(H6="",H6=0),"",J6/H6-1) -> -0.36795606 | M6: =IF(OR(H6="",H6=0),"",J6/(H6*'Supuestos y fuentes'!$B$5)-1) -> -0.38564936 | N6: =IF(OR(K6="",K6=0),"",J6/K6-1) -> -0.21500973 | O6: =IF(OR(H6="",H6=0),"Nuevo",IF(M6<=-0.995,"Desaparece",IF(M6<-'Supuestos y fuentes'!$B$6,"Baja",IF(M6>'Supuestos y fuentes'!$B$6,"Sube","Se mantiene")))) -> Baja | P6: No | Q6: No | R6: Es la fuente de financiamiento del aporte CEAC en Educación: no se suma al total para no contar dos veces.
A7: 6 | B7: Directo | C7: Directo | D7: Red Sismológica Nacional (convenio con la U. de Chile) | E7: 05 | F7: Interior · SENAPRED · 24.03.018 «Universidad de Chile - Red Sismológica» | G7: 04.01.24.03.018 | H7: 3228426 | I7: 3228426 | J7: 3321405 | K7: 3321405 | L7: =IF(OR(H7="",H7=0),"",J7/H7-1) -> 0.028800103 | M7: =IF(OR(H7="",H7=0),"",J7/(H7*'Supuestos y fuentes'!$B$5)-1) -> 9.9716847e-08 | N7: =IF(OR(K7="",K7=0),"",J7/K7-1) -> 0 | O7: =IF(OR(H7="",H7=0),"Nuevo",IF(M7<=-0.995,"Desaparece",IF(M7<-'Supuestos y fuentes'!$B$6,"Baja",IF(M7>'Supuestos y fuentes'!$B$6,"Sube","Se mantiene")))) -> Se mantiene | P7: Sí | Q7: No
A8: 7 | B8: Directo | C8: Salud | D8: Ley N° 21.621 – Hospital Clínico Universidad de Chile | E8: 16 | F8: Salud · FONASA · Programa 01 · 24.03.411 | G8: 02.01.24.03.411 | H8: 24766279 | I8: 40598445 | J8: 25479548 | K8: 25479548 | L8: =IF(OR(H8="",H8=0),"",J8/H8-1) -> 0.028800007 | M8: =IF(OR(H8="",H8=0),"",J8/(H8*'Supuestos y fuentes'!$B$5)-1) -> 6.4679329e-09 | N8: =IF(OR(K8="",K8=0),"",J8/K8-1) -> 0 | O8: =IF(OR(H8="",H8=0),"Nuevo",IF(M8<=-0.995,"Desaparece",IF(M8<-'Supuestos y fuentes'!$B$6,"Baja",IF(M8>'Supuestos y fuentes'!$B$6,"Sube","Se mantiene")))) -> Se mantiene | P8: Sí | Q8: No
A9: 8 | B9: Directo | C9: Salud | D9: Instituto de Nutrición y Tecnología de los Alimentos (INTA) | E9: 16 | F9: Salud · Subs. Redes Asistenciales · 24.03.434 | G9: 10.01.24.03.434 | H9: 560864 | I9: 1104864 | J9: 577017 | K9: 577017 | L9: =IF(OR(H9="",H9=0),"",J9/H9-1) -> 0.028800208 | M9: =IF(OR(H9="",H9=0),"",J9/(H9*'Supuestos y fuentes'!$B$5)-1) -> 2.0242042e-07 | N9: =IF(OR(K9="",K9=0),"",J9/K9-1) -> 0 | O9: =IF(OR(H9="",H9=0),"Nuevo",IF(M9<=-0.995,"Desaparece",IF(M9<-'Supuestos y fuentes'!$B$6,"Baja",IF(M9>'Supuestos y fuentes'!$B$6,"Sube","Se mantiene")))) -> Se mantiene | P9: Sí | Q9: No
A10: 9 | B10: Directo | C10: Salud | D10: Equipamiento e infraestructura del Hospital Clínico (glosa) | E10: 16 | F10: Salud · Subs. Redes Asistenciales · Inversión Sectorial de Salud · glosa 01 | G10: (glosa) | H10: 6200000 | J10: 6200000 | L10: =IF(OR(H10="",H10=0),"",J10/H10-1) -> 0 | M10: =IF(OR(H10="",H10=0),"",J10/(H10*'Supuestos y fuentes'!$B$5)-1) -> -0.027993779 | N10: =IF(OR(K10="",K10=0),"",J10/K10-1) | O10: =IF(OR(H10="",H10=0),"Nuevo",IF(M10<=-0.995,"Desaparece",IF(M10<-'Supuestos y fuentes'!$B$6,"Baja",IF(M10>'Supuestos y fuentes'!$B$6,"Sube","Se mantiene")))) -> Baja | P10: No | Q10: No | R10: Tope «hasta» fijado en la glosa 01, igual en 2026 y 2027 (en términos reales, −2,8%). No se suma a los totales porque es un máximo dentro de otra línea.
A11: 10 | B11: Institucional | C11: Institucional | D11: Aporte Fiscal Directo (Art. 2° DFL 4/1981) — universidades estatales | E11: 09 | F11: Educación · Fortalecimiento ES Pública · 24.03.196 | G11: 90.02.24.03.196 | H11: 182424894 | I11: 184386151 | J11: 182048369 | K11: 187678731 | L11: =IF(OR(H11="",H11=0),"",J11/H11-1) -> -0.0020640001 | M11: =IF(OR(H11="",H11=0),"",J11/(H11*'Supuestos y fuentes'!$B$5)-1) -> -0.03 | N11: =IF(OR(K11="",K11=0),"",J11/K11-1) -> -0.03 | O11: =IF(OR(H11="",H11=0),"Nuevo",IF(M11<=-0.995,"Desaparece",IF(M11<-'Supuestos y fuentes'!$B$6,"Baja",IF(M11>'Supuestos y fuentes'!$B$6,"Sube","Se mantiene")))) -> Baja | P11: Sí | Q11: No
A12: 11 | B12: Institucional | C12: Institucional | D12: Aporte Institucional Universidades Estatales, Ley 21.094 (corriente + capital) | E12: 09 | F12: Educación · Fortalecimiento ES Pública · 24.03.807 + 33.03.410 | G12: 90.02.24.03.807 + 90.02.33.03.410 | H12: 113365900 | I12: 112365900 | J12: 102417508 | K12: 115602037 | L12: =IF(OR(H12="",H12=0),"",J12/H12-1) -> -0.096575708 | M12: =IF(OR(H12="",H12=0),"",J12/(H12*'Supuestos y fuentes'!$B$5)-1) -> -0.12186597 | N12: =IF(OR(K12="",K12=0),"",J12/K12-1) -> -0.11405101 | O12: =IF(OR(H12="",H12=0),"Nuevo",IF(M12<=-0.995,"Desaparece",IF(M12<-'Supuestos y fuentes'!$B$6,"Baja",IF(M12>'Supuestos y fuentes'!$B$6,"Sube","Se mantiene")))) -> Baja | P12: Sí | Q12: No
A13: 12 | B13: Institucional | C13: Institucional | D13: Plan de Fortalecimiento Universidades Estatales (corriente + infraestructura) | E13: 09 | F13: Educación · Fortalecimiento ES Pública · 24.03.221 + 33.03.417 | G13: 90.02.24.03.221 + 90.02.33.03.417 | H13: 21623037 | I13: 21623037 | J13: 14514957 | K13: 22245781 | L13: =IF(OR(H13="",H13=0),"",J13/H13-1) -> -0.32872718 | M13: =IF(OR(H13="",H13=0),"",J13/(H13*'Supuestos y fuentes'!$B$5)-1) -> -0.34751864 | N13: =IF(OR(K13="",K13=0),"",J13/K13-1) -> -0.34751866 | O13: =IF(OR(H13="",H13=0),"Nuevo",IF(M13<=-0.995,"Desaparece",IF(M13<-'Supuestos y fuentes'!$B$6,"Baja",IF(M13>'Supuestos y fuentes'!$B$6,"Sube","Se mantiene")))) -> Baja | P13: Sí | Q13: No
A14: 13 | B14: Institucional | C14: Institucional | D14: Ley N° 21.043 – Incentivo al retiro de académicos y profesionales | E14: 09 | F14: Educación · Fortalecimiento ES Pública · 24.03.857 | G14: 90.02.24.03.857 | H14: 14894015 | I14: 9894015 | J14: 10177155 | K14: 10178963 | L14: =IF(OR(H14="",H14=0),"",J14/H14-1) -> -0.31669499 | M14: =IF(OR(H14="",H14=0),"",J14/(H14*'Supuestos y fuentes'!$B$5)-1) -> -0.33582328 | N14: =IF(OR(K14="",K14=0),"",J14/K14-1) -> -0.00017762124 | O14: =IF(OR(H14="",H14=0),"Nuevo",IF(M14<=-0.995,"Desaparece",IF(M14<-'Supuestos y fuentes'!$B$6,"Baja",IF(M14>'Supuestos y fuentes'!$B$6,"Sube","Se mantiene")))) -> Baja | P14: Sí | Q14: No
A15: 14 | B15: Institucional | C15: Institucional | D15: Aplicación Ley N° 20.374 | E15: 09 | F15: Educación · Fortalecimiento ES Pública · 24.03.208 | G15: 90.02.24.03.208 | H15: 4223530 | I15: 4223530 | J15: 4345168 | K15: 4345168 | L15: =IF(OR(H15="",H15=0),"",J15/H15-1) -> 0.02880008 | M15: =IF(OR(H15="",H15=0),"",J15/(H15*'Supuestos y fuentes'!$B$5)-1) -> 7.7327281e-08 | N15: =IF(OR(K15="",K15=0),"",J15/K15-1) -> 0 | O15: =IF(OR(H15="",H15=0),"Nuevo",IF(M15<=-0.995,"Desaparece",IF(M15<-'Supuestos y fuentes'!$B$6,"Baja",IF(M15>'Supuestos y fuentes'!$B$6,"Sube","Se mantiene")))) -> Se mantiene | P15: Sí | Q15: No
A16: 15 | B16: Institucional | C16: Institucional | D16: Aplicación Ley N° 20.996 | E16: 09 | F16: Educación · Fortalecimiento ES Pública · 24.03.855 | G16: 90.02.24.03.855 | H16: 7436742 | I16: 7436742 | J16: 7664968 | K16: 7650920 | L16: =IF(OR(H16="",H16=0),"",J16/H16-1) -> 0.030688976 | M16: =IF(OR(H16="",H16=0),"",J16/(H16*'Supuestos y fuentes'!$B$5)-1) -> 0.0018360968 | N16: =IF(OR(K16="",K16=0),"",J16/K16-1) -> 0.0018361191 | O16: =IF(OR(H16="",H16=0),"Nuevo",IF(M16<=-0.995,"Desaparece",IF(M16<-'Supuestos y fuentes'!$B$6,"Baja",IF(M16>'Supuestos y fuentes'!$B$6,"Sube","Se mantiene")))) -> Se mantiene | P16: Sí | Q16: No
A17: 16 | B17: Institucional | C17: Institucional | D17: Fondo Desarrollo Institucional art. 1° DFL 4 (estatales) | E17: 09 | F17: Educación · Fortalecimiento ES Pública · 24.03.202 | G17: 90.02.24.03.202 | H17: 992681 | I17: 992681 | J17: 1605320 | K17: 1021270 | L17: =IF(OR(H17="",H17=0),"",J17/H17-1) -> 0.61715596 | M17: =IF(OR(H17="",H17=0),"",J17/(H17*'Supuestos y fuentes'!$B$5)-1) -> 0.57188566 | N17: =IF(OR(K17="",K17=0),"",J17/K17-1) -> 0.57188599 | O17: =IF(OR(H17="",H17=0),"Nuevo",IF(M17<=-0.995,"Desaparece",IF(M17<-'Supuestos y fuentes'!$B$6,"Baja",IF(M17>'Supuestos y fuentes'!$B$6,"Sube","Se mantiene")))) -> Sube | P17: Sí | Q17: No
A18: 17 | B18: Institucional | C18: Institucional | D18: Aplicación letra a) Art. 71 bis Ley N° 18.591 (estatales) | E18: 09 | F18: Educación · Fortalecimiento ES Pública · 33.03.036 | G18: 90.02.33.03.036 | H18: 1487171 | I18: 1487171 | J18: 1053492 | K18: 1530002 | L18: =IF(OR(H18="",H18=0),"",J18/H18-1) -> -0.29161341 | M18: =IF(OR(H18="",H18=0),"",J18/(H18*'Supuestos y fuentes'!$B$5)-1) -> -0.31144382 | N18: =IF(OR(K18="",K18=0),"",J18/K18-1) -> -0.31144404 | O18: =IF(OR(H18="",H18=0),"Nuevo",IF(M18<=-0.995,"Desaparece",IF(M18<-'Supuestos y fuentes'!$B$6,"Baja",IF(M18>'Supuestos y fuentes'!$B$6,"Sube","Se mantiene")))) -> Baja | P18: Sí | Q18: No
A19: 18 | B19: Institucional | C19: Institucional | D19: Aporte para el Desarrollo de Actividades de Interés Nacional (otras estatales) | E19: 09 | F19: Educación · Fortalecimiento ES Pública · 24.03.858 | G19: (glosa) | H19: 3093000 | J19: 0 | L19: =IF(OR(H19="",H19=0),"",J19/H19-1) -> -1 | M19: =IF(OR(H19="",H19=0),"",J19/(H19*'Supuestos y fuentes'!$B$5)-1) -> -1 | N19: =IF(OR(K19="",K19=0),"",J19/K19-1) | O19: =IF(OR(H19="",H19=0),"Nuevo",IF(M19<=-0.995,"Desaparece",IF(M19<-'Supuestos y fuentes'!$B$6,"Baja",IF(M19>'Supuestos y fuentes'!$B$6,"Sube","Se mantiene")))) -> Desaparece | P19: No | Q19: No | R19: Desaparece en el Proyecto 2027.
A20: 19 | B20: Institucional | C20: Institucional | D20: Financiamiento Institucional para la Gratuidad – Universidades | E20: 09 | F20: Educación · Educación Superior · 24.03.198 | G20: 90.03.24.03.198 | H20: 1805133752 | I20: 1785084425 | J20: 1819372635 | K20: 1836494856 | L20: =IF(OR(H20="",H20=0),"",J20/H20-1) -> 0.0078879933 | M20: =IF(OR(H20="",H20=0),"",J20/(H20*'Supuestos y fuentes'!$B$5)-1) -> -0.020326601 | N20: =IF(OR(K20="",K20=0),"",J20/K20-1) -> -0.0093233155 | O20: =IF(OR(H20="",H20=0),"Nuevo",IF(M20<=-0.995,"Desaparece",IF(M20<-'Supuestos y fuentes'!$B$6,"Baja",IF(M20>'Supuestos y fuentes'!$B$6,"Sube","Se mantiene")))) -> Baja | P20: Sí | Q20: No
A21: 20 | B21: Institucional | C21: Institucional | D21: Fondo de Desarrollo Institucional (corriente + infraestructura) | E21: 09 | F21: Educación · Educación Superior · 24.03.802 + 33.01.401 | G21: 90.03.24.03.802 + 90.03.33.01.401 | H21: 13343911 | I21: 10343911 | J21: 13990228 | K21: 10641816 | L21: =IF(OR(H21="",H21=0),"",J21/H21-1) -> 0.04843535 | M21: =IF(OR(H21="",H21=0),"",J21/(H21*'Supuestos y fuentes'!$B$5)-1) -> 0.019085682 | N21: =IF(OR(K21="",K21=0),"",J21/K21-1) -> 0.31464667 | O21: =IF(OR(H21="",H21=0),"Nuevo",IF(M21<=-0.995,"Desaparece",IF(M21<-'Supuestos y fuentes'!$B$6,"Baja",IF(M21>'Supuestos y fuentes'!$B$6,"Sube","Se mantiene")))) -> Sube | P21: Sí | Q21: No
A22: 21 | B22: Institucional | C22: Institucional | D22: Sistema de Acceso a la Educación Superior (Ley 21.091) | E22: 09 | F22: Educación · Subs. Educación Superior · 24.09.007 | G22: 90.01.24.09.007 | H22: 17310024 | I22: 17310024 | J22: 16580607 | K22: 17808553 | L22: =IF(OR(H22="",H22=0),"",J22/H22-1) -> -0.042138416 | M22: =IF(OR(H22="",H22=0),"",J22/(H22*'Supuestos y fuentes'!$B$5)-1) -> -0.068952582 | N22: =IF(OR(K22="",K22=0),"",J22/K22-1) -> -0.068952598 | O22: =IF(OR(H22="",H22=0),"Nuevo",IF(M22<=-0.995,"Desaparece",IF(M22<-'Supuestos y fuentes'!$B$6,"Baja",IF(M22>'Supuestos y fuentes'!$B$6,"Sube","Se mantiene")))) -> Baja | P22: Sí | Q22: No
A23: 22 | B23: Institucional | C23: Institucional | D23: Consejo de Rectores (CRUCH) | E23: 09 | F23: Educación · Capítulo 13 | G23: 13 | H23: 519655 | J23: 561519 | K23: 550395 | L23: =IF(OR(H23="",H23=0),"",J23/H23-1) -> 0.080561142 | M23: =IF(OR(H23="",H23=0),"",J23/(H23*'Supuestos y fuentes'!$B$5)-1) -> 0.050312152 | N23: =IF(OR(K23="",K23=0),"",J23/K23-1) -> 0.020210939 | O23: =IF(OR(H23="",H23=0),"Nuevo",IF(M23<=-0.995,"Desaparece",IF(M23<-'Supuestos y fuentes'!$B$6,"Baja",IF(M23>'Supuestos y fuentes'!$B$6,"Sube","Se mantiene")))) -> Sube | P23: Sí | Q23: No
A24: 23 | B24: Estudiantes | C24: Estudiantes | D24: Becas de Educación Superior (Bicentenario, Juan Gómez Millas, etc.) | E24: 09 | F24: Educación · Educación Superior · 24.03.200 | G24: 90.03.24.03.200 | H24: 231751216 | I24: 227751216 | J24: 240490355 | K24: 234310451 | L24: =IF(OR(H24="",H24=0),"",J24/H24-1) -> 0.03770914 | M24: =IF(OR(H24="",H24=0),"",J24/(H24*'Supuestos y fuentes'!$B$5)-1) -> 0.0086597393 | N24: =IF(OR(K24="",K24=0),"",J24/K24-1) -> 0.026374854 | O24: =IF(OR(H24="",H24=0),"Nuevo",IF(M24<=-0.995,"Desaparece",IF(M24<-'Supuestos y fuentes'!$B$6,"Baja",IF(M24>'Supuestos y fuentes'!$B$6,"Sube","Se mantiene")))) -> Sube | P24: Sí | Q24: No
A25: 24 | B25: Estudiantes | C25: Estudiantes | D25: Becas de Mantención para Educación Superior (JUNAEB) | E25: 09 | F25: Educación · JUNAEB · Becas y Asistencialidad · 24.01.252 | G25: 09.03.24.01.252 | H25: 351975501 | I25: 349475501 | J25: 358405481 | K25: 359540397 | L25: =IF(OR(H25="",H25=0),"",J25/H25-1) -> 0.01826826 | M25: =IF(OR(H25="",H25=0),"",J25/(H25*'Supuestos y fuentes'!$B$5)-1) -> -0.010236917 | N25: =IF(OR(K25="",K25=0),"",J25/K25-1) -> -0.0031565744 | O25: =IF(OR(H25="",H25=0),"Nuevo",IF(M25<=-0.995,"Desaparece",IF(M25<-'Supuestos y fuentes'!$B$6,"Baja",IF(M25>'Supuestos y fuentes'!$B$6,"Sube","Se mantiene")))) -> Baja | P25: Sí | Q25: No
A26: 25 | B26: Estudiantes | C26: Estudiantes | D26: Programa de Becas Indígenas (JUNAEB) | E26: 09 | F26: Educación · JUNAEB · 24.01.189 + 24.09.189 | G26: 09.03.24.01.189 + 09.03.24.09.189 | H26: 37846636 | I26: 37746636 | J26: 34950366 | K26: 38833739 | L26: =IF(OR(H26="",H26=0),"",J26/H26-1) -> -0.076526484 | M26: =IF(OR(H26="",H26=0),"",J26/(H26*'Supuestos y fuentes'!$B$5)-1) -> -0.102378 | N26: =IF(OR(K26="",K26=0),"",J26/K26-1) -> -0.099999977 | O26: =IF(OR(H26="",H26=0),"Nuevo",IF(M26<=-0.995,"Desaparece",IF(M26<-'Supuestos y fuentes'!$B$6,"Baja",IF(M26>'Supuestos y fuentes'!$B$6,"Sube","Se mantiene")))) -> Baja | P26: Sí | Q26: No
A27: 26 | B27: Estudiantes | C27: Estudiantes | D27: Beca Presidente de la República (JUNAEB) | E27: 09 | F27: Educación · JUNAEB · 24.01.250 | G27: 09.03.24.01.250 | H27: 34714450 | I27: 34614450 | J27: 35611346 | K27: 35611346 | L27: =IF(OR(H27="",H27=0),"",J27/H27-1) -> 0.025836388 | M27: =IF(OR(H27="",H27=0),"",J27/(H27*'Supuestos y fuentes'!$B$5)-1) -> -0.0028806493 | N27: =IF(OR(K27="",K27=0),"",J27/K27-1) -> 0 | O27: =IF(OR(H27="",H27=0),"Nuevo",IF(M27<=-0.995,"Desaparece",IF(M27<-'Supuestos y fuentes'!$B$6,"Baja",IF(M27>'Supuestos y fuentes'!$B$6,"Sube","Se mantiene")))) -> Se mantiene | P27: Sí | Q27: No
A28: 27 | B28: Estudiantes | C28: Estudiantes | D28: Programa de Acceso a la Educación Superior (PACE) | E28: 09 | F28: Educación · Educación Superior · 24.03.052 | G28: 90.03.24.03.052 | H28: 20682565 | I28: 20682565 | J28: 20607522 | K28: 21278223 | L28: =IF(OR(H28="",H28=0),"",J28/H28-1) -> -0.0036283217 | M28: =IF(OR(H28="",H28=0),"",J28/(H28*'Supuestos y fuentes'!$B$5)-1) -> -0.03152053 | N28: =IF(OR(K28="",K28=0),"",J28/K28-1) -> -0.031520536 | O28: =IF(OR(H28="",H28=0),"Nuevo",IF(M28<=-0.995,"Desaparece",IF(M28<-'Supuestos y fuentes'!$B$6,"Baja",IF(M28>'Supuestos y fuentes'!$B$6,"Sube","Se mantiene")))) -> Baja | P28: Sí | Q28: No
A29: 28 | B29: Estudiantes | C29: Estudiantes | D29: Recargo Aplicación Ley N° 20.027 (CAE) | E29: 09 | F29: Educación · Educación Superior · 24.01.806 | G29: 90.03.24.01.806 | H29: 115402158 | I29: 115402158 | J29: 127838997 | K29: 118725740 | L29: =IF(OR(H29="",H29=0),"",J29/H29-1) -> 0.10776955 | M29: =IF(OR(H29="",H29=0),"",J29/(H29*'Supuestos y fuentes'!$B$5)-1) -> 0.076758897 | N29: =IF(OR(K29="",K29=0),"",J29/K29-1) -> 0.076758898 | O29: =IF(OR(H29="",H29=0),"Nuevo",IF(M29<=-0.995,"Desaparece",IF(M29<-'Supuestos y fuentes'!$B$6,"Baja",IF(M29>'Supuestos y fuentes'!$B$6,"Sube","Se mantiene")))) -> Sube | P29: Sí | Q29: No
A30: 29 | B30: Estudiantes | C30: Estudiantes | D30: Aplicación Ley N° 20.634 (beneficios CAE) | E30: 09 | F30: Educación · Educación Superior · 24.01.805 | G30: 90.03.24.01.805 | H30: 22794929 | I30: 22794929 | J30: 20494191 | K30: 23451423 | L30: =IF(OR(H30="",H30=0),"",J30/H30-1) -> -0.10093201 | M30: =IF(OR(H30="",H30=0),"",J30/(H30*'Supuestos y fuentes'!$B$5)-1) -> -0.12610032 | N30: =IF(OR(K30="",K30=0),"",J30/K30-1) -> -0.12610032 | O30: =IF(OR(H30="",H30=0),"Nuevo",IF(M30<=-0.995,"Desaparece",IF(M30<-'Supuestos y fuentes'!$B$6,"Baja",IF(M30>'Supuestos y fuentes'!$B$6,"Sube","Se mantiene")))) -> Baja | P30: Sí | Q30: No
A31: 30 | B31: Estudiantes | C31: Estudiantes | D31: Apoyo a estudiantes de ES en situación de discapacidad (SENADIS) | E31: 21 | F31: Desarrollo Social · SENADIS · 24.01.001 | G31: 07.01.24.01.001 | H31: 1369559 | I31: 1369559 | J31: 1409002 | K31: 1409002 | L31: =IF(OR(H31="",H31=0),"",J31/H31-1) -> 0.028799782 | M31: =IF(OR(H31="",H31=0),"",J31/(H31*'Supuestos y fuentes'!$B$5)-1) -> -2.1234884e-07 | N31: =IF(OR(K31="",K31=0),"",J31/K31-1) -> 0 | O31: =IF(OR(H31="",H31=0),"Nuevo",IF(M31<=-0.995,"Desaparece",IF(M31<-'Supuestos y fuentes'!$B$6,"Baja",IF(M31>'Supuestos y fuentes'!$B$6,"Sube","Se mantiene")))) -> Se mantiene | P31: Sí | Q31: No
A32: 31 | B32: Investigación | C32: Investigación | D32: FONDECYT | E32: 30 | F32: Ciencia · ANID · 24.01.160 + 24.03.160 | G32: 02.01.24.01.160 + 02.01.24.03.160 | H32: 197235204 | I32: 192679299 | J32: 201264631 | K32: 198228462 | L32: =IF(OR(H32="",H32=0),"",J32/H32-1) -> 0.020429553 | M32: =IF(OR(H32="",H32=0),"",J32/(H32*'Supuestos y fuentes'!$B$5)-1) -> -0.0081361268 | N32: =IF(OR(K32="",K32=0),"",J32/K32-1) -> 0.015316514 | O32: =IF(OR(H32="",H32=0),"Nuevo",IF(M32<=-0.995,"Desaparece",IF(M32<-'Supuestos y fuentes'!$B$6,"Baja",IF(M32>'Supuestos y fuentes'!$B$6,"Sube","Se mantiene")))) -> Baja | P32: Sí | Q32: No
A33: 32 | B33: Investigación | C33: Investigación | D33: FONDEF | E33: 30 | F33: Ciencia · ANID · 24.01.161 + 24.03.161 | G33: 02.01.24.01.161 + 02.01.24.03.161 | H33: 48019112 | I33: 45062505 | J33: 38266406 | K33: 46360303 | L33: =IF(OR(H33="",H33=0),"",J33/H33-1) -> -0.20310051 | M33: =IF(OR(H33="",H33=0),"",J33/(H33*'Supuestos y fuentes'!$B$5)-1) -> -0.22540874 | N33: =IF(OR(K33="",K33=0),"",J33/K33-1) -> -0.1745868 | O33: =IF(OR(H33="",H33=0),"Nuevo",IF(M33<=-0.995,"Desaparece",IF(M33<-'Supuestos y fuentes'!$B$6,"Baja",IF(M33>'Supuestos y fuentes'!$B$6,"Sube","Se mantiene")))) -> Baja | P33: Sí | Q33: No
A34: 33 | B34: Investigación | C34: Investigación | D34: Programa de Investigación Asociativa (PIA) | E34: 30 | F34: Ciencia · ANID · 24.01.170 + 24.03.170 | G34: 02.01.24.01.170 + 02.01.24.03.170 | H34: 18724849 | I34: 16853655 | J34: 14344131 | K34: 17339039 | L34: =IF(OR(H34="",H34=0),"",J34/H34-1) -> -0.23395211 | M34: =IF(OR(H34="",H34=0),"",J34/(H34*'Supuestos y fuentes'!$B$5)-1) -> -0.25539669 | N34: =IF(OR(K34="",K34=0),"",J34/K34-1) -> -0.1727263 | O34: =IF(OR(H34="",H34=0),"Nuevo",IF(M34<=-0.995,"Desaparece",IF(M34<-'Supuestos y fuentes'!$B$6,"Baja",IF(M34>'Supuestos y fuentes'!$B$6,"Sube","Se mantiene")))) -> Baja | P34: Sí | Q34: No
A35: 34 | B35: Investigación | C35: Investigación | D35: Centros de Investigación Aplicada | E35: 30 | F35: Ciencia · ANID · 24.01.171 + 24.03.171 | G35: 02.01.24.01.171 + 02.01.24.03.171 | H35: 30249486 | I35: 29339948 | J35: 30184938 | K35: 30184939 | L35: =IF(OR(H35="",H35=0),"",J35/H35-1) -> -0.0021338544 | M35: =IF(OR(H35="",H35=0),"",J35/(H35*'Supuestos y fuentes'!$B$5)-1) -> -0.030067899 | N35: =IF(OR(K35="",K35=0),"",J35/K35-1) -> -3.3129105e-08 | O35: =IF(OR(H35="",H35=0),"Nuevo",IF(M35<=-0.995,"Desaparece",IF(M35<-'Supuestos y fuentes'!$B$6,"Baja",IF(M35>'Supuestos y fuentes'!$B$6,"Sube","Se mantiene")))) -> Baja | P35: Sí | Q35: No
... A39: 38 | B39: Investigación | C39: Investigación | D39: Becas Chile | E39: 30 | F39: Ciencia · ANID · 24.01.230 | G39: 02.01.24.01.230 | H39: 23717921 | I39: 22407155 | J39: 21810871 | K39: 23052481 | L39: =IF(OR(H39="",H39=0),"",J39/H39-1) -> -0.080405445 | M39: =IF(OR(H39="",H39=0),"",J39/(H39*'Supuestos y fuentes'!$B$5)-1) -> -0.10614837 | N39: =IF(OR(K39="",K39=0),"",J39/K39-1) -> -0.053860146 | O39: =IF(OR(H39="",H39=0),"Nuevo",IF(M39<=-0.995,"Desaparece",IF(M39<-'Supuestos y fuentes'!$B$6,"Baja",IF(M39>'Supuestos y fuentes'!$B$6,"Sube","Se mantiene")))) -> Baja | P39: Sí | Q39: No
A40: 39 | B40: Investigación | C40: Investigación | D40: Acceso a la Información Electrónica para CyT (bases de datos científicas) | E40: 30 | F40: Ciencia · ANID · 24.01.229 + 24.08.229 | G40: 02.01.24.01.229 + 02.01.24.08.229 | H40: 14832351 | I40: 14832351 | J40: 14191355 | K40: 15259523 | L40: =IF(OR(H40="",H40=0),"",J40/H40-1) -> -0.043216075 | M40: =IF(OR(H40="",H40=0),"",J40/(H40*'Supuestos y fuentes'!$B$5)-1) -> -0.070000073 | N40: =IF(OR(K40="",K40=0),"",J40/K40-1) -> -0.070000091 | O40: =IF(OR(H40="",H40=0),"Nuevo",IF(M40<=-0.995,"Desaparece",IF(M40<-'Supuestos y fuentes'!$B$6,"Baja",IF(M40>'Supuestos y fuentes'!$B$6,"Sube","Se mantiene")))) -> Baja | P40: Sí | Q40: No | R40: En 2027 la mayor parte se reclasifica a «Instituciones Privadas Ejecutoras de Políticas Públicas» (24.08); se suman ambas.
A41: 40 | B41: Investigación | C41: Investigación | D41: FONDEQUIP (equipamiento científico) | E41: 30 | F41: Ciencia · ANID · 33.01.002 | G41: 02.01.33.01.002 | H41: 15526660 | I41: 13338928 | J41: 2921656 | K41: 13723089 | L41: =IF(OR(H41="",H41=0),"",J41/H41-1) -> -0.81182972 | M41: =IF(OR(H41="",H41=0),"",J41/(H41*'Supuestos y fuentes'!$B$5)-1) -> -0.81709731 | N41: =IF(OR(K41="",K41=0),"",J41/K41-1) -> -0.78709925 | O41: =IF(OR(H41="",H41=0),"Nuevo",IF(M41<=-0.995,"Desaparece",IF(M41<-'Supuestos y fuentes'!$B$6,"Baja",IF(M41>'Supuestos y fuentes'!$B$6,"Sube","Se mantiene")))) -> Baja | P41: Sí | Q41: No
A42: 41 | B42: Investigación | C42: Investigación | D42: Programa de Inserción de Investigadores | E42: 30 | F42: Ciencia · ANID · 24.01.231 + 24.03.231 | G42: 02.01.24.01.231 + 02.01.24.03.231 | H42: 5069449 | I42: 4141188 | J42: 2646057 | K42: 4260453 | L42: =IF(OR(H42="",H42=0),"",J42/H42-1) -> -0.47803854 | M42: =IF(OR(H42="",H42=0),"",J42/(H42*'Supuestos y fuentes'!$B$5)-1) -> -0.49265021 | N42: =IF(OR(K42="",K42=0),"",J42/K42-1) -> -0.3789259 | O42: =IF(OR(H42="",H42=0),"Nuevo",IF(M42<=-0.995,"Desaparece",IF(M42<-'Supuestos y fuentes'!$B$6,"Baja",IF(M42>'Supuestos y fuentes'!$B$6,"Sube","Se mantiene")))) -> Baja | P42: Sí | Q42: No
A43: 42 | B43: Investigación | C43: Investigación | D43: Iniciativa Científica Milenio | E43: 30 | F43: Ciencia · Subs. CTCI · Fondo de Innovación, Ciencia y Tecnología · 24.02.018 | G43: 01.02.24.02.018 | H43: 15580548 | I43: 14935742 | J43: 14956355 | K43: 15365891 | L43: =IF(OR(H43="",H43=0),"",J43/H43-1) -> -0.040062326 | M43: =IF(OR(H43="",H43=0),"",J43/(H43*'Supuestos y fuentes'!$B$5)-1) -> -0.06693461 | N43: =IF(OR(K43="",K43=0),"",J43/K43-1) -> -0.026652278 | O43: =IF(OR(H43="",H43=0),"Nuevo",IF(M43<=-0.995,"Desaparece",IF(M43<-'Supuestos y fuentes'!$B$6,"Baja",IF(M43>'Supuestos y fuentes'!$B$6,"Sube","Se mantiene")))) -> Baja | P43: Sí | Q43: No
...

Sheet Bloques
A1: Bloque | B1: Ley 2026 (miles $) | C1: Proyecto 2027 (miles $) | D1: Variación nominal | E1: Variación real
A2: Directo (convenio MINEDUC, CEAC, Red Sismológica, Hospital Clínico, INTA) | B2: =SUMIFS(Líneas!$H$2:$H$49,Líneas!$B$2:$B$49,"Directo",Líneas!$P$2:$P$49,"Sí")-SUMIFS(Líneas!$H$2:$H$49,Líneas!$B$2:$B$49,"Directo",Líneas!$P$2:$P$49,"Sí",Líneas!$Q$2:$Q$49,"Sí") -> 44257722 | C2: =SUMIFS(Líneas!$J$2:$J$49,Líneas!$B$2:$B$49,"Directo",Líneas!$P$2:$P$49,"Sí") -> 41408512 | D2: =C2/B2-1 -> -0.064377692 | E2: =C2/(B2*'Supuestos y fuentes'!$B$5)-1 -> -0.090569296
A3: Institucional (universidades estatales y sistema) | B3: =SUMIFS(Líneas!$H$2:$H$49,Líneas!$B$2:$B$49,"Institucional",Líneas!$P$2:$P$49,"Sí")-SUMIFS(Líneas!$H$2:$H$49,Líneas!$B$2:$B$49,"Institucional",Líneas!$P$2:$P$49,"Sí",Líneas!$Q$2:$Q$49,"Sí") -> 2182755312 | C3: =SUMIFS(Líneas!$J$2:$J$49,Líneas!$B$2:$B$49,"Institucional",Líneas!$P$2:$P$49,"Sí") -> 2174331926 | D3: =C3/B3-1 -> -0.003859061 | E3: =C3/(B3*'Supuestos y fuentes'!$B$5)-1 -> -0.031744811
A4: Estudiantes (becas, acceso y crédito) | B4: =SUMIFS(Líneas!$H$2:$H$49,Líneas!$B$2:$B$49,"Estudiantes",Líneas!$P$2:$P$49,"Sí")-SUMIFS(Líneas!$H$2:$H$49,Líneas!$B$2:$B$49,"Estudiantes",Líneas!$P$2:$P$49,"Sí",Líneas!$Q$2:$Q$49,"Sí") -> 816537014 | C4: =SUMIFS(Líneas!$J$2:$J$49,Líneas!$B$2:$B$49,"Estudiantes",Líneas!$P$2:$P$49,"Sí") -> 839807260 | D4: =C4/B4-1 -> 0.028498703 | E4: =C4/(B4*'Supuestos y fuentes'!$B$5)-1 -> -0.00029286238
A5: Investigación y postgrado (ANID, Milenio) | B5: =SUMIFS(Líneas!$H$2:$H$49,Líneas!$B$2:$B$49,"Investigación",Líneas!$P$2:$P$49,"Sí")-SUMIFS(Líneas!$H$2:$H$49,Líneas!$B$2:$B$49,"Investigación",Líneas!$P$2:$P$49,"Sí",Líneas!$Q$2:$Q$49,"Sí") -> 502147362 | C5: =SUMIFS(Líneas!$J$2:$J$49,Líneas!$B$2:$B$49,"Investigación",Líneas!$P$2:$P$49,"Sí") -> 463420693 | D5: =C5/B5-1 -> -0.07712212 | E5: =C5/(B5*'Supuestos y fuentes'!$B$5)-1 -> -0.10295696
A6: Institucional sin gratuidad | B6: =B3-Líneas!H20 -> 377621560 | C6: =C3-Líneas!J20 -> 354959291 | D6: =C6/B6-1 -> -0.060013176 | E6: =C6/(B6*'Supuestos y fuentes'!$B$5)-1 -> -0.086326959
A8: Sumas de la hoja «Líneas» con «Se suma en bloques» = Sí. Para Directo, la Ley 2026 de riesgo sísmico y CEAC no se suma porque en 2026 estaba dentro del convenio (columna Q).

Sheet Supuestos y fuentes
A1: Recortes 2027 a la U. de Chile — datos de la sección «Recortes U. de Chile»
A2: Myriam Barahona · Senadora Universitaria · Actualizado al 7 de octubre de 2026
A4: Supuesto | B4: Valor | C4: Fuente / nota
A5: Inflactor 2027 (Ley 2026 → pesos de 2027) | B5: 1.0288 | C5: Inflactor 2,88% que DIPRES aplica en el Proyecto de Ley de Presupuestos 2027. Puedes cambiarlo: todas las variaciones reales se recalculan.
A6: Umbral «se mantiene» (± variación real) | B6: 0.005 | C6: Entre −0,5% y +0,5% real la línea solo recibe el reajuste por inflación.
A8: Cómo leer
A9: • Montos en miles de pesos, como en las fuentes. Las celdas en azul son datos de entrada; las negras son fórmulas.
A10: • Variación nominal = Proyecto 2027 / Ley 2026 − 1.
A11: • Variación real = Proyecto 2027 / (Ley 2026 × inflactor) − 1. Negativa: la línea compra menos que en 2026.
A12: • Vs base DIPRES = Proyecto 2027 / base oficial − 1. La base es la Ley 2026 + reajuste y leyes especiales − recortes de 2026, en $ de 2027.
A13: • Vigente 2026: presupuesto con las modificaciones del año, a agosto de 2026.
A14: • Mismo perímetro: las líneas que en 2027 se dividen o cambian de código se suman (ver columna «Códigos 2027»).
A15: • Bloques sin doble conteo: no se suman las líneas marcadas «No» en «Se suma en bloques» (fuentes de otra línea y topes «hasta» de glosas).
A16: • Riesgo sísmico y CEAC: en 2026 estaban dentro del convenio «Universidad de Chile» (glosa 04); por eso su Ley 2026 no se suma en los bloques.
A17: • Fondos compartidos (institucional, estudiantes, investigación): el presupuesto fija el total nacional, no lo que recibe la U. de Chile.
A19: Fuentes
A20: Ley de Presupuestos 2026 (Ley N° 21.796), DIPRES | C20: https://www.dipres.gob.cl/597/w3-multipropertyvalues-15199-37782.html
A21: Proyecto de Ley de Presupuestos 2027 por programa y Cuadros Comparativos Analíticos 2026-2027, DIPRES | C21: https://www.dipres.gob.cl/597/w3-multipropertyvalues-15168-38403.html
A22: Análisis completo en la página de Myriam Barahona | C22: https://www.myriambarahona.cl/recortes-2027
